{"timestamp": 1746797952.849377, "type": "task_execution_error", "content": {"task": "Unknown task", "error_type": "UnboundLocalError", "error_message": "cannot access local variable 'time' where it is not associated with a value", "traceback": "Traceback (most recent call last):\n  File \"/Users/ohoriryosuke/20250417_synthepseai/SynthepseAI/workspace/project_7c969cef-8988-4432-ad6a-6f48698f6ae2/task_a6cb8a83-fec5-47c5-8cea-c95af54c182b.py\", line 325, in prepare_task\n    task_start_time = time.time()\n                      ^^^^\nUnboundLocalError: cannot access local variable 'time' where it is not associated with a value\n\nDuring handling of the above exception, another exception occurred:\n\nTraceback (most recent call last):\n  File \"/Users/ohoriryosuke/20250417_synthepseai/SynthepseAI/workspace/project_7c969cef-8988-4432-ad6a-6f48698f6ae2/task_a6cb8a83-fec5-47c5-8cea-c95af54c182b.py\", line 931, in main\n    task_start_time = prepare_task()\n                      ^^^^^^^^^^^^^^\n  File \"/Users/ohoriryosuke/20250417_synthepseai/SynthepseAI/workspace/project_7c969cef-8988-4432-ad6a-6f48698f6ae2/task_a6cb8a83-fec5-47c5-8cea-c95af54c182b.py\", line 385, in prepare_task\n    return time.time()\n           ^^^^\nUnboundLocalError: cannot access local variable 'time' where it is not associated with a value\n"}}\n{"timestamp": 1746797952.849613, "type": "knowledge_update", "content": {"subject": "エラーパターン: UnboundLocalError", "original_fact": null, "new_fact": "タスク実行中に発生: cannot access local variable 'time' where it is not associated with a value", "confidence": 0.7, "source": null, "success": true}}\n{"timestamp": 1746798221.718003, "type": "task_execution_error", "content": {"task": "Unknown task", "error_type": "UnboundLocalError", "error_message": "cannot access local variable 'time' where it is not associated with a value", "traceback": "Traceback (most recent call last):\n  File \"/Users/ohoriryosuke/20250417_synthepseai/SynthepseAI/workspace/project_7c969cef-8988-4432-ad6a-6f48698f6ae2/task_5725cd4a-895c-4437-a887-159b4730e493.py\", line 325, in prepare_task\n    task_start_time = time.time()\n                      ^^^^\nUnboundLocalError: cannot access local variable 'time' where it is not associated with a value\n\nDuring handling of the above exception, another exception occurred:\n\nTraceback (most recent call last):\n  File \"/Users/ohoriryosuke/20250417_synthepseai/SynthepseAI/workspace/project_7c969cef-8988-4432-ad6a-6f48698f6ae2/task_5725cd4a-895c-4437-a887-159b4730e493.py\", line 931, in main\n    task_start_time = prepare_task()\n                      ^^^^^^^^^^^^^^\n  File \"/Users/ohoriryosuke/20250417_synthepseai/SynthepseAI/workspace/project_7c969cef-8988-4432-ad6a-6f48698f6ae2/task_5725cd4a-895c-4437-a887-159b4730e493.py\", line 385, in prepare_task\n    return time.time()\n           ^^^^\nUnboundLocalError: cannot access local variable 'time' where it is not associated with a value\n"}}\n{"timestamp": 1746798221.718752, "type": "knowledge_update", "content": {"subject": "エラーパターン: UnboundLocalError", "original_fact": "タスク実行中に発生: cannot access local variable 'time' where it is not associated with a value", "new_fact": "タスク実行中に発生: cannot access local variable 'time' where it is not associated with a value", "confidence": 0.7, "source": null, "success": true}}\n{"timestamp": 1746798270.060629, "type": "task_execution_error", "content": {"task": "Unknown task", "error_type": "UnboundLocalError", "error_message": "cannot access local variable 'time' where it is not associated with a value", "traceback": "Traceback (most recent call last):\n  File \"/Users/ohoriryosuke/20250417_synthepseai/SynthepseAI/workspace/project_7c969cef-8988-4432-ad6a-6f48698f6ae2/task_ac89d73a-b231-4cc6-beb0-57c012e31c8b.py\", line 325, in prepare_task\n    task_start_time = time.time()\n                      ^^^^\nUnboundLocalError: cannot access local variable 'time' where it is not associated with a value\n\nDuring handling of the above exception, another exception occurred:\n\nTraceback (most recent call last):\n  File \"/Users/ohoriryosuke/20250417_synthepseai/SynthepseAI/workspace/project_7c969cef-8988-4432-ad6a-6f48698f6ae2/task_ac89d73a-b231-4cc6-beb0-57c012e31c8b.py\", line 931, in main\n    task_start_time = prepare_task()\n                      ^^^^^^^^^^^^^^\n  File \"/Users/ohoriryosuke/20250417_synthepseai/SynthepseAI/workspace/project_7c969cef-8988-4432-ad6a-6f48698f6ae2/task_ac89d73a-b231-4cc6-beb0-57c012e31c8b.py\", line 385, in prepare_task\n    return time.time()\n           ^^^^\nUnboundLocalError: cannot access local variable 'time' where it is not associated with a value\n"}}\n{"timestamp": 1746798270.060937, "type": "knowledge_update", "content": {"subject": "エラーパターン: UnboundLocalError", "original_fact": "タスク実行中に発生: cannot access local variable 'time' where it is not associated with a value", "new_fact": "タスク実行中に発生: cannot access local variable 'time' where it is not associated with a value", "confidence": 0.7, "source": null, "success": true}}\n{"timestamp": 1746798315.8139892, "type": "task_execution_error", "content": {"task": "Unknown task", "error_type": "UnboundLocalError", "error_message": "cannot access local variable 'time' where it is not associated with a value", "traceback": "Traceback (most recent call last):\n  File \"/Users/ohoriryosuke/20250417_synthepseai/SynthepseAI/workspace/project_7c969cef-8988-4432-ad6a-6f48698f6ae2/task_2cba1322-63a2-461b-9a7f-097c43e8a984.py\", line 325, in prepare_task\n    task_start_time = time.time()\n                      ^^^^\nUnboundLocalError: cannot access local variable 'time' where it is not associated with a value\n\nDuring handling of the above exception, another exception occurred:\n\nTraceback (most recent call last):\n  File \"/Users/ohoriryosuke/20250417_synthepseai/SynthepseAI/workspace/project_7c969cef-8988-4432-ad6a-6f48698f6ae2/task_2cba1322-63a2-461b-9a7f-097c43e8a984.py\", line 931, in main\n    task_start_time = prepare_task()\n                      ^^^^^^^^^^^^^^\n  File \"/Users/ohoriryosuke/20250417_synthepseai/SynthepseAI/workspace/project_7c969cef-8988-4432-ad6a-6f48698f6ae2/task_2cba1322-63a2-461b-9a7f-097c43e8a984.py\", line 385, in prepare_task\n    return time.time()\n           ^^^^\nUnboundLocalError: cannot access local variable 'time' where it is not associated with a value\n"}}\n{"timestamp": 1746798315.814274, "type": "knowledge_update", "content": {"subject": "エラーパターン: UnboundLocalError", "original_fact": "タスク実行中に発生: cannot access local variable 'time' where it is not associated with a value", "new_fact": "タスク実行中に発生: cannot access local variable 'time' where it is not associated with a value", "confidence": 0.7, "source": null, "success": true}}\n{"timestamp": 1746798362.915021, "type": "task_execution_error", "content": {"task": "Unknown task", "error_type": "UnboundLocalError", "error_message": "cannot access local variable 'time' where it is not associated with a value", "traceback": "Traceback (most recent call last):\n  File \"/Users/ohoriryosuke/20250417_synthepseai/SynthepseAI/workspace/project_7c969cef-8988-4432-ad6a-6f48698f6ae2/task_4b15b61c-2387-4334-be82-56bf790724b4.py\", line 325, in prepare_task\n    task_start_time = time.time()\n                      ^^^^\nUnboundLocalError: cannot access local variable 'time' where it is not associated with a value\n\nDuring handling of the above exception, another exception occurred:\n\nTraceback (most recent call last):\n  File \"/Users/ohoriryosuke/20250417_synthepseai/SynthepseAI/workspace/project_7c969cef-8988-4432-ad6a-6f48698f6ae2/task_4b15b61c-2387-4334-be82-56bf790724b4.py\", line 931, in main\n    task_start_time = prepare_task()\n                      ^^^^^^^^^^^^^^\n  File \"/Users/ohoriryosuke/20250417_synthepseai/SynthepseAI/workspace/project_7c969cef-8988-4432-ad6a-6f48698f6ae2/task_4b15b61c-2387-4334-be82-56bf790724b4.py\", line 385, in prepare_task\n    return time.time()\n           ^^^^\nUnboundLocalError: cannot access local variable 'time' where it is not associated with a value\n"}}\n{"timestamp": 1746798362.915324, "type": "knowledge_update", "content": {"subject": "エラーパターン: UnboundLocalError", "original_fact": "タスク実行中に発生: cannot access local variable 'time' where it is not associated with a value", "new_fact": "タスク実行中に発生: cannot access local variable 'time' where it is not associated with a value", "confidence": 0.7, "source": null, "success": true}}\n{"timestamp": 1746798411.7591228, "type": "task_execution_error", "content": {"task": "Unknown task", "error_type": "UnboundLocalError", "error_message": "cannot access local variable 'time' where it is not associated with a value", "traceback": "Traceback (most recent call last):\n  File \"/Users/ohoriryosuke/20250417_synthepseai/SynthepseAI/workspace/project_7c969cef-8988-4432-ad6a-6f48698f6ae2/task_843289b6-1d9b-4fee-928a-ba49341324bf.py\", line 325, in prepare_task\n    task_start_time = time.time()\n                      ^^^^\nUnboundLocalError: cannot access local variable 'time' where it is not associated with a value\n\nDuring handling of the above exception, another exception occurred:\n\nTraceback (most recent call last):\n  File \"/Users/ohoriryosuke/20250417_synthepseai/SynthepseAI/workspace/project_7c969cef-8988-4432-ad6a-6f48698f6ae2/task_843289b6-1d9b-4fee-928a-ba49341324bf.py\", line 931, in main\n    task_start_time = prepare_task()\n                      ^^^^^^^^^^^^^^\n  File \"/Users/ohoriryosuke/20250417_synthepseai/SynthepseAI/workspace/project_7c969cef-8988-4432-ad6a-6f48698f6ae2/task_843289b6-1d9b-4fee-928a-ba49341324bf.py\", line 385, in prepare_task\n    return time.time()\n           ^^^^\nUnboundLocalError: cannot access local variable 'time' where it is not associated with a value\n"}}\n{"timestamp": 1746798411.759409, "type": "knowledge_update", "content": {"subject": "エラーパターン: UnboundLocalError", "original_fact": "タスク実行中に発生: cannot access local variable 'time' where it is not associated with a value", "new_fact": "タスク実行中に発生: cannot access local variable 'time' where it is not associated with a value", "confidence": 0.7, "source": null, "success": true}}\n{"timestamp": 1746798469.2343528, "type": "task_execution_error", "content": {"task": "Unknown task", "error_type": "UnboundLocalError", "error_message": "cannot access local variable 'time' where it is not associated with a value", "traceback": "Traceback (most recent call last):\n  File \"/Users/ohoriryosuke/20250417_synthepseai/SynthepseAI/workspace/project_7c969cef-8988-4432-ad6a-6f48698f6ae2/task_cfba5660-e272-46d1-a552-9559d0e295e9.py\", line 325, in prepare_task\n    task_start_time = time.time()\n                      ^^^^\nUnboundLocalError: cannot access local variable 'time' where it is not associated with a value\n\nDuring handling of the above exception, another exception occurred:\n\nTraceback (most recent call last):\n  File \"/Users/ohoriryosuke/20250417_synthepseai/SynthepseAI/workspace/project_7c969cef-8988-4432-ad6a-6f48698f6ae2/task_cfba5660-e272-46d1-a552-9559d0e295e9.py\", line 931, in main\n    task_start_time = prepare_task()\n                      ^^^^^^^^^^^^^^\n  File \"/Users/ohoriryosuke/20250417_synthepseai/SynthepseAI/workspace/project_7c969cef-8988-4432-ad6a-6f48698f6ae2/task_cfba5660-e272-46d1-a552-9559d0e295e9.py\", line 385, in prepare_task\n    return time.time()\n           ^^^^\nUnboundLocalError: cannot access local variable 'time' where it is not associated with a value\n"}}\n{"timestamp": 1746798469.234625, "type": "knowledge_update", "content": {"subject": "エラーパターン: UnboundLocalError", "original_fact": "タスク実行中に発生: cannot access local variable 'time' where it is not associated with a value", "new_fact": "タスク実行中に発生: cannot access local variable 'time' where it is not associated with a value", "confidence": 0.7, "source": null, "success": true}}\n