{"timestamp": 1747792956.708289, "type": "task_execution_error", "content": {"task": "Unknown task", "error_type": "UnboundLocalError", "error_message": "cannot access local variable 'time' where it is not associated with a value", "traceback": "Traceback (most recent call last):\n  File \"/Users/ohoriryosuke/20250417_synthepseai/SynthepseAI/workspace/project_d62f9d7f-a7d1-40ca-b26b-51464e44fda8/task_6c82d76a-393f-44a1-b8a3-74a6682fc49c.py\", line 325, in prepare_task\n    task_start_time = time.time()\n                      ^^^^\nUnboundLocalError: cannot access local variable 'time' where it is not associated with a value\n\nDuring handling of the above exception, another exception occurred:\n\nTraceback (most recent call last):\n  File \"/Users/ohoriryosuke/20250417_synthepseai/SynthepseAI/workspace/project_d62f9d7f-a7d1-40ca-b26b-51464e44fda8/task_6c82d76a-393f-44a1-b8a3-74a6682fc49c.py\", line 885, in main\n    task_start_time = prepare_task()\n                      ^^^^^^^^^^^^^^\n  File \"/Users/ohoriryosuke/20250417_synthepseai/SynthepseAI/workspace/project_d62f9d7f-a7d1-40ca-b26b-51464e44fda8/task_6c82d76a-393f-44a1-b8a3-74a6682fc49c.py\", line 385, in prepare_task\n    return time.time()\n           ^^^^\nUnboundLocalError: cannot access local variable 'time' where it is not associated with a value\n"}}\n{"timestamp": 1747792956.709715, "type": "knowledge_update", "content": {"subject": "エラーパターン: UnboundLocalError", "original_fact": null, "new_fact": "タスク実行中に発生: {str(e)}", "confidence": 0.7, "source": null, "success": true}}\n{"timestamp": 1747793006.80262, "type": "task_execution_error", "content": {"task": "Unknown task", "error_type": "UnboundLocalError", "error_message": "cannot access local variable 'time' where it is not associated with a value", "traceback": "Traceback (most recent call last):\n  File \"/Users/ohoriryosuke/20250417_synthepseai/SynthepseAI/workspace/project_d62f9d7f-a7d1-40ca-b26b-51464e44fda8/task_ee87a719-707f-48c8-a2b7-5ba4b040346b.py\", line 326, in prepare_task\n    task_start_time = time.time()\n                      ^^^^\nUnboundLocalError: cannot access local variable 'time' where it is not associated with a value\n\nDuring handling of the above exception, another exception occurred:\n\nTraceback (most recent call last):\n  File \"/Users/ohoriryosuke/20250417_synthepseai/SynthepseAI/workspace/project_d62f9d7f-a7d1-40ca-b26b-51464e44fda8/task_ee87a719-707f-48c8-a2b7-5ba4b040346b.py\", line 886, in main\n    task_start_time = prepare_task()\n                      ^^^^^^^^^^^^^^\n  File \"/Users/ohoriryosuke/20250417_synthepseai/SynthepseAI/workspace/project_d62f9d7f-a7d1-40ca-b26b-51464e44fda8/task_ee87a719-707f-48c8-a2b7-5ba4b040346b.py\", line 386, in prepare_task\n    return time.time()\n           ^^^^\nUnboundLocalError: cannot access local variable 'time' where it is not associated with a value\n"}}\n{"timestamp": 1747793006.8029592, "type": "knowledge_update", "content": {"subject": "エラーパターン: UnboundLocalError", "original_fact": "タスク実行中に発生: {str(e)}", "new_fact": "タスク実行中に発生: {str(e)}", "confidence": 0.7, "source": null, "success": true}}\n{"timestamp": 1747793058.6926222, "type": "task_execution_error", "content": {"task": "Unknown task", "error_type": "UnboundLocalError", "error_message": "cannot access local variable 'time' where it is not associated with a value", "traceback": "Traceback (most recent call last):\n  File \"/Users/ohoriryosuke/20250417_synthepseai/SynthepseAI/workspace/project_d62f9d7f-a7d1-40ca-b26b-51464e44fda8/task_c88c51c6-2ccb-4a24-8115-075ccd58673e.py\", line 325, in prepare_task\n    task_start_time = time.time()\n                      ^^^^\nUnboundLocalError: cannot access local variable 'time' where it is not associated with a value\n\nDuring handling of the above exception, another exception occurred:\n\nTraceback (most recent call last):\n  File \"/Users/ohoriryosuke/20250417_synthepseai/SynthepseAI/workspace/project_d62f9d7f-a7d1-40ca-b26b-51464e44fda8/task_c88c51c6-2ccb-4a24-8115-075ccd58673e.py\", line 885, in main\n    task_start_time = prepare_task()\n                      ^^^^^^^^^^^^^^\n  File \"/Users/ohoriryosuke/20250417_synthepseai/SynthepseAI/workspace/project_d62f9d7f-a7d1-40ca-b26b-51464e44fda8/task_c88c51c6-2ccb-4a24-8115-075ccd58673e.py\", line 385, in prepare_task\n    return time.time()\n           ^^^^\nUnboundLocalError: cannot access local variable 'time' where it is not associated with a value\n"}}\n{"timestamp": 1747793058.6928709, "type": "knowledge_update", "content": {"subject": "エラーパターン: UnboundLocalError", "original_fact": "タスク実行中に発生: {str(e)}", "new_fact": "タスク実行中に発生: {str(e)}", "confidence": 0.7, "source": null, "success": true}}\n{"timestamp": 1747793115.6000168, "type": "task_execution_error", "content": {"task": "Unknown task", "error_type": "UnboundLocalError", "error_message": "cannot access local variable 'time' where it is not associated with a value", "traceback": "Traceback (most recent call last):\n  File \"/Users/ohoriryosuke/20250417_synthepseai/SynthepseAI/workspace/project_d62f9d7f-a7d1-40ca-b26b-51464e44fda8/task_854cd5d1-d475-492d-9870-eed9cad60459.py\", line 325, in prepare_task\n    task_start_time = time.time()\n                      ^^^^\nUnboundLocalError: cannot access local variable 'time' where it is not associated with a value\n\nDuring handling of the above exception, another exception occurred:\n\nTraceback (most recent call last):\n  File \"/Users/ohoriryosuke/20250417_synthepseai/SynthepseAI/workspace/project_d62f9d7f-a7d1-40ca-b26b-51464e44fda8/task_854cd5d1-d475-492d-9870-eed9cad60459.py\", line 885, in main\n    task_start_time = prepare_task()\n                      ^^^^^^^^^^^^^^\n  File \"/Users/ohoriryosuke/20250417_synthepseai/SynthepseAI/workspace/project_d62f9d7f-a7d1-40ca-b26b-51464e44fda8/task_854cd5d1-d475-492d-9870-eed9cad60459.py\", line 385, in prepare_task\n    return time.time()\n           ^^^^\nUnboundLocalError: cannot access local variable 'time' where it is not associated with a value\n"}}\n{"timestamp": 1747793115.6003, "type": "knowledge_update", "content": {"subject": "エラーパターン: UnboundLocalError", "original_fact": "タスク実行中に発生: {str(e)}", "new_fact": "タスク実行中に発生: {str(e)}", "confidence": 0.7, "source": null, "success": true}}\n{"timestamp": 1747793171.249825, "type": "task_execution_error", "content": {"task": "Unknown task", "error_type": "UnboundLocalError", "error_message": "cannot access local variable 'time' where it is not associated with a value", "traceback": "Traceback (most recent call last):\n  File \"/Users/ohoriryosuke/20250417_synthepseai/SynthepseAI/workspace/project_d62f9d7f-a7d1-40ca-b26b-51464e44fda8/task_3d026a3a-9103-4d52-b781-cca80e7e7f03.py\", line 325, in prepare_task\n    task_start_time = time.time()\n                      ^^^^\nUnboundLocalError: cannot access local variable 'time' where it is not associated with a value\n\nDuring handling of the above exception, another exception occurred:\n\nTraceback (most recent call last):\n  File \"/Users/ohoriryosuke/20250417_synthepseai/SynthepseAI/workspace/project_d62f9d7f-a7d1-40ca-b26b-51464e44fda8/task_3d026a3a-9103-4d52-b781-cca80e7e7f03.py\", line 885, in main\n    task_start_time = prepare_task()\n                      ^^^^^^^^^^^^^^\n  File \"/Users/ohoriryosuke/20250417_synthepseai/SynthepseAI/workspace/project_d62f9d7f-a7d1-40ca-b26b-51464e44fda8/task_3d026a3a-9103-4d52-b781-cca80e7e7f03.py\", line 385, in prepare_task\n    return time.time()\n           ^^^^\nUnboundLocalError: cannot access local variable 'time' where it is not associated with a value\n"}}\n{"timestamp": 1747793171.2501051, "type": "knowledge_update", "content": {"subject": "エラーパターン: UnboundLocalError", "original_fact": "タスク実行中に発生: {str(e)}", "new_fact": "タスク実行中に発生: {str(e)}", "confidence": 0.7, "source": null, "success": true}}\n{"timestamp": 1747793216.976235, "type": "task_execution_error", "content": {"task": "Unknown task", "error_type": "UnboundLocalError", "error_message": "cannot access local variable 'time' where it is not associated with a value", "traceback": "Traceback (most recent call last):\n  File \"/Users/ohoriryosuke/20250417_synthepseai/SynthepseAI/workspace/project_d62f9d7f-a7d1-40ca-b26b-51464e44fda8/task_78231c72-583a-44c1-8840-260bf1e375d7.py\", line 325, in prepare_task\n    task_start_time = time.time()\n                      ^^^^\nUnboundLocalError: cannot access local variable 'time' where it is not associated with a value\n\nDuring handling of the above exception, another exception occurred:\n\nTraceback (most recent call last):\n  File \"/Users/ohoriryosuke/20250417_synthepseai/SynthepseAI/workspace/project_d62f9d7f-a7d1-40ca-b26b-51464e44fda8/task_78231c72-583a-44c1-8840-260bf1e375d7.py\", line 885, in main\n    task_start_time = prepare_task()\n                      ^^^^^^^^^^^^^^\n  File \"/Users/ohoriryosuke/20250417_synthepseai/SynthepseAI/workspace/project_d62f9d7f-a7d1-40ca-b26b-51464e44fda8/task_78231c72-583a-44c1-8840-260bf1e375d7.py\", line 385, in prepare_task\n    return time.time()\n           ^^^^\nUnboundLocalError: cannot access local variable 'time' where it is not associated with a value\n"}}\n{"timestamp": 1747793216.976541, "type": "knowledge_update", "content": {"subject": "エラーパターン: UnboundLocalError", "original_fact": "タスク実行中に発生: {str(e)}", "new_fact": "タスク実行中に発生: {str(e)}", "confidence": 0.7, "source": null, "success": true}}\n{"timestamp": 1747793264.726675, "type": "task_execution_error", "content": {"task": "Unknown task", "error_type": "UnboundLocalError", "error_message": "cannot access local variable 'time' where it is not associated with a value", "traceback": "Traceback (most recent call last):\n  File \"/Users/ohoriryosuke/20250417_synthepseai/SynthepseAI/workspace/project_d62f9d7f-a7d1-40ca-b26b-51464e44fda8/task_3fc5650a-b40d-4412-ac37-9f8b398def9d.py\", line 325, in prepare_task\n    task_start_time = time.time()\n                      ^^^^\nUnboundLocalError: cannot access local variable 'time' where it is not associated with a value\n\nDuring handling of the above exception, another exception occurred:\n\nTraceback (most recent call last):\n  File \"/Users/ohoriryosuke/20250417_synthepseai/SynthepseAI/workspace/project_d62f9d7f-a7d1-40ca-b26b-51464e44fda8/task_3fc5650a-b40d-4412-ac37-9f8b398def9d.py\", line 885, in main\n    task_start_time = prepare_task()\n                      ^^^^^^^^^^^^^^\n  File \"/Users/ohoriryosuke/20250417_synthepseai/SynthepseAI/workspace/project_d62f9d7f-a7d1-40ca-b26b-51464e44fda8/task_3fc5650a-b40d-4412-ac37-9f8b398def9d.py\", line 385, in prepare_task\n    return time.time()\n           ^^^^\nUnboundLocalError: cannot access local variable 'time' where it is not associated with a value\n"}}\n{"timestamp": 1747793264.7269151, "type": "knowledge_update", "content": {"subject": "エラーパターン: UnboundLocalError", "original_fact": "タスク実行中に発生: {str(e)}", "new_fact": "タスク実行中に発生: {str(e)}", "confidence": 0.7, "source": null, "success": true}}\n{"timestamp": 1747793323.346145, "type": "task_execution_error", "content": {"task": "Unknown task", "error_type": "UnboundLocalError", "error_message": "cannot access local variable 'time' where it is not associated with a value", "traceback": "Traceback (most recent call last):\n  File \"/Users/ohoriryosuke/20250417_synthepseai/SynthepseAI/workspace/project_d62f9d7f-a7d1-40ca-b26b-51464e44fda8/task_70cdeda8-7ccb-4228-9628-ab6a0eaaa60b.py\", line 325, in prepare_task\n    task_start_time = time.time()\n                      ^^^^\nUnboundLocalError: cannot access local variable 'time' where it is not associated with a value\n\nDuring handling of the above exception, another exception occurred:\n\nTraceback (most recent call last):\n  File \"/Users/ohoriryosuke/20250417_synthepseai/SynthepseAI/workspace/project_d62f9d7f-a7d1-40ca-b26b-51464e44fda8/task_70cdeda8-7ccb-4228-9628-ab6a0eaaa60b.py\", line 885, in main\n    task_start_time = prepare_task()\n                      ^^^^^^^^^^^^^^\n  File \"/Users/ohoriryosuke/20250417_synthepseai/SynthepseAI/workspace/project_d62f9d7f-a7d1-40ca-b26b-51464e44fda8/task_70cdeda8-7ccb-4228-9628-ab6a0eaaa60b.py\", line 385, in prepare_task\n    return time.time()\n           ^^^^\nUnboundLocalError: cannot access local variable 'time' where it is not associated with a value\n"}}\n{"timestamp": 1747793323.346433, "type": "knowledge_update", "content": {"subject": "エラーパターン: UnboundLocalError", "original_fact": "タスク実行中に発生: {str(e)}", "new_fact": "タスク実行中に発生: {str(e)}", "confidence": 0.7, "source": null, "success": true}}\n{"timestamp": 1747793393.0949, "type": "task_execution_error", "content": {"task": "Unknown task", "error_type": "UnboundLocalError", "error_message": "cannot access local variable 'time' where it is not associated with a value", "traceback": "Traceback (most recent call last):\n  File \"/Users/ohoriryosuke/20250417_synthepseai/SynthepseAI/workspace/project_d62f9d7f-a7d1-40ca-b26b-51464e44fda8/task_5bca6bde-1dc0-4f81-ba73-b6cbf857b2a8.py\", line 325, in prepare_task\n    task_start_time = time.time()\n                      ^^^^\nUnboundLocalError: cannot access local variable 'time' where it is not associated with a value\n\nDuring handling of the above exception, another exception occurred:\n\nTraceback (most recent call last):\n  File \"/Users/ohoriryosuke/20250417_synthepseai/SynthepseAI/workspace/project_d62f9d7f-a7d1-40ca-b26b-51464e44fda8/task_5bca6bde-1dc0-4f81-ba73-b6cbf857b2a8.py\", line 885, in main\n    task_start_time = prepare_task()\n                      ^^^^^^^^^^^^^^\n  File \"/Users/ohoriryosuke/20250417_synthepseai/SynthepseAI/workspace/project_d62f9d7f-a7d1-40ca-b26b-51464e44fda8/task_5bca6bde-1dc0-4f81-ba73-b6cbf857b2a8.py\", line 385, in prepare_task\n    return time.time()\n           ^^^^\nUnboundLocalError: cannot access local variable 'time' where it is not associated with a value\n"}}\n{"timestamp": 1747793393.095167, "type": "knowledge_update", "content": {"subject": "エラーパターン: UnboundLocalError", "original_fact": "タスク実行中に発生: {str(e)}", "new_fact": "タスク実行中に発生: {str(e)}", "confidence": 0.7, "source": null, "success": true}}\n