{"timestamp": 1747194494.006037, "type": "task_execution_error", "content": {"task": "Unknown task", "error_type": "UnboundLocalError", "error_message": "cannot access local variable 'time' where it is not associated with a value", "traceback": "Traceback (most recent call last):\n  File \"/Users/ohoriryosuke/20250417_synthepseai/SynthepseAI/workspace/project_429014e3-f05f-48f2-adf4-81de7dd29ac3/task_69f65c42-c15b-47b6-b53d-d886adf0fc03.py\", line 325, in prepare_task\n    task_start_time = time.time()\n                      ^^^^\nUnboundLocalError: cannot access local variable 'time' where it is not associated with a value\n\nDuring handling of the above exception, another exception occurred:\n\nTraceback (most recent call last):\n  File \"/Users/ohoriryosuke/20250417_synthepseai/SynthepseAI/workspace/project_429014e3-f05f-48f2-adf4-81de7dd29ac3/task_69f65c42-c15b-47b6-b53d-d886adf0fc03.py\", line 885, in main\n    task_start_time = prepare_task()\n                      ^^^^^^^^^^^^^^\n  File \"/Users/ohoriryosuke/20250417_synthepseai/SynthepseAI/workspace/project_429014e3-f05f-48f2-adf4-81de7dd29ac3/task_69f65c42-c15b-47b6-b53d-d886adf0fc03.py\", line 385, in prepare_task\n    return time.time()\n           ^^^^\nUnboundLocalError: cannot access local variable 'time' where it is not associated with a value\n"}}\n{"timestamp": 1747194494.006336, "type": "knowledge_update", "content": {"subject": "エラーパターン: UnboundLocalError", "original_fact": null, "new_fact": "タスク実行中に発生: {str(e)}", "confidence": 0.7, "source": null, "success": true}}\n{"timestamp": 1747194539.147727, "type": "task_execution_error", "content": {"task": "Unknown task", "error_type": "UnboundLocalError", "error_message": "cannot access local variable 'time' where it is not associated with a value", "traceback": "Traceback (most recent call last):\n  File \"/Users/ohoriryosuke/20250417_synthepseai/SynthepseAI/workspace/project_429014e3-f05f-48f2-adf4-81de7dd29ac3/task_79bc88c0-1d69-4f2b-a59c-ff270cfc590e.py\", line 325, in prepare_task\n    task_start_time = time.time()\n                      ^^^^\nUnboundLocalError: cannot access local variable 'time' where it is not associated with a value\n\nDuring handling of the above exception, another exception occurred:\n\nTraceback (most recent call last):\n  File \"/Users/ohoriryosuke/20250417_synthepseai/SynthepseAI/workspace/project_429014e3-f05f-48f2-adf4-81de7dd29ac3/task_79bc88c0-1d69-4f2b-a59c-ff270cfc590e.py\", line 885, in main\n    task_start_time = prepare_task()\n                      ^^^^^^^^^^^^^^\n  File \"/Users/ohoriryosuke/20250417_synthepseai/SynthepseAI/workspace/project_429014e3-f05f-48f2-adf4-81de7dd29ac3/task_79bc88c0-1d69-4f2b-a59c-ff270cfc590e.py\", line 385, in prepare_task\n    return time.time()\n           ^^^^\nUnboundLocalError: cannot access local variable 'time' where it is not associated with a value\n"}}\n{"timestamp": 1747194539.148386, "type": "knowledge_update", "content": {"subject": "エラーパターン: UnboundLocalError", "original_fact": "タスク実行中に発生: {str(e)}", "new_fact": "タスク実行中に発生: {str(e)}", "confidence": 0.7, "source": null, "success": true}}\n{"timestamp": 1747194583.7085571, "type": "task_execution_error", "content": {"task": "Unknown task", "error_type": "UnboundLocalError", "error_message": "cannot access local variable 'time' where it is not associated with a value", "traceback": "Traceback (most recent call last):\n  File \"/Users/ohoriryosuke/20250417_synthepseai/SynthepseAI/workspace/project_429014e3-f05f-48f2-adf4-81de7dd29ac3/task_156dda5b-355c-4c3c-99ed-5f0f23e8cee1.py\", line 325, in prepare_task\n    task_start_time = time.time()\n                      ^^^^\nUnboundLocalError: cannot access local variable 'time' where it is not associated with a value\n\nDuring handling of the above exception, another exception occurred:\n\nTraceback (most recent call last):\n  File \"/Users/ohoriryosuke/20250417_synthepseai/SynthepseAI/workspace/project_429014e3-f05f-48f2-adf4-81de7dd29ac3/task_156dda5b-355c-4c3c-99ed-5f0f23e8cee1.py\", line 885, in main\n    task_start_time = prepare_task()\n                      ^^^^^^^^^^^^^^\n  File \"/Users/ohoriryosuke/20250417_synthepseai/SynthepseAI/workspace/project_429014e3-f05f-48f2-adf4-81de7dd29ac3/task_156dda5b-355c-4c3c-99ed-5f0f23e8cee1.py\", line 385, in prepare_task\n    return time.time()\n           ^^^^\nUnboundLocalError: cannot access local variable 'time' where it is not associated with a value\n"}}\n{"timestamp": 1747194583.708946, "type": "knowledge_update", "content": {"subject": "エラーパターン: UnboundLocalError", "original_fact": "タスク実行中に発生: {str(e)}", "new_fact": "タスク実行中に発生: {str(e)}", "confidence": 0.7, "source": null, "success": true}}\n{"timestamp": 1747194629.840359, "type": "task_execution_error", "content": {"task": "Unknown task", "error_type": "UnboundLocalError", "error_message": "cannot access local variable 'time' where it is not associated with a value", "traceback": "Traceback (most recent call last):\n  File \"/Users/ohoriryosuke/20250417_synthepseai/SynthepseAI/workspace/project_429014e3-f05f-48f2-adf4-81de7dd29ac3/task_7bf2fa83-0696-4ea8-a74d-8df521539139.py\", line 325, in prepare_task\n    task_start_time = time.time()\n                      ^^^^\nUnboundLocalError: cannot access local variable 'time' where it is not associated with a value\n\nDuring handling of the above exception, another exception occurred:\n\nTraceback (most recent call last):\n  File \"/Users/ohoriryosuke/20250417_synthepseai/SynthepseAI/workspace/project_429014e3-f05f-48f2-adf4-81de7dd29ac3/task_7bf2fa83-0696-4ea8-a74d-8df521539139.py\", line 885, in main\n    task_start_time = prepare_task()\n                      ^^^^^^^^^^^^^^\n  File \"/Users/ohoriryosuke/20250417_synthepseai/SynthepseAI/workspace/project_429014e3-f05f-48f2-adf4-81de7dd29ac3/task_7bf2fa83-0696-4ea8-a74d-8df521539139.py\", line 385, in prepare_task\n    return time.time()\n           ^^^^\nUnboundLocalError: cannot access local variable 'time' where it is not associated with a value\n"}}\n{"timestamp": 1747194629.8408709, "type": "knowledge_update", "content": {"subject": "エラーパターン: UnboundLocalError", "original_fact": "タスク実行中に発生: {str(e)}", "new_fact": "タスク実行中に発生: {str(e)}", "confidence": 0.7, "source": null, "success": true}}\n{"timestamp": 1747194680.687658, "type": "task_execution_error", "content": {"task": "Unknown task", "error_type": "UnboundLocalError", "error_message": "cannot access local variable 'time' where it is not associated with a value", "traceback": "Traceback (most recent call last):\n  File \"/Users/ohoriryosuke/20250417_synthepseai/SynthepseAI/workspace/project_429014e3-f05f-48f2-adf4-81de7dd29ac3/task_0f35312b-3109-4374-aa08-31deada08959.py\", line 325, in prepare_task\n    task_start_time = time.time()\n                      ^^^^\nUnboundLocalError: cannot access local variable 'time' where it is not associated with a value\n\nDuring handling of the above exception, another exception occurred:\n\nTraceback (most recent call last):\n  File \"/Users/ohoriryosuke/20250417_synthepseai/SynthepseAI/workspace/project_429014e3-f05f-48f2-adf4-81de7dd29ac3/task_0f35312b-3109-4374-aa08-31deada08959.py\", line 885, in main\n    task_start_time = prepare_task()\n                      ^^^^^^^^^^^^^^\n  File \"/Users/ohoriryosuke/20250417_synthepseai/SynthepseAI/workspace/project_429014e3-f05f-48f2-adf4-81de7dd29ac3/task_0f35312b-3109-4374-aa08-31deada08959.py\", line 385, in prepare_task\n    return time.time()\n           ^^^^\nUnboundLocalError: cannot access local variable 'time' where it is not associated with a value\n"}}\n{"timestamp": 1747194680.688394, "type": "knowledge_update", "content": {"subject": "エラーパターン: UnboundLocalError", "original_fact": "タスク実行中に発生: {str(e)}", "new_fact": "タスク実行中に発生: {str(e)}", "confidence": 0.7, "source": null, "success": true}}\n{"timestamp": 1747194716.649575, "type": "task_execution_error", "content": {"task": "Unknown task", "error_type": "UnboundLocalError", "error_message": "cannot access local variable 'time' where it is not associated with a value", "traceback": "Traceback (most recent call last):\n  File \"/Users/ohoriryosuke/20250417_synthepseai/SynthepseAI/workspace/project_429014e3-f05f-48f2-adf4-81de7dd29ac3/task_7f011f25-060f-47ae-a519-d602ad7c105e.py\", line 325, in prepare_task\n    task_start_time = time.time()\n                      ^^^^\nUnboundLocalError: cannot access local variable 'time' where it is not associated with a value\n\nDuring handling of the above exception, another exception occurred:\n\nTraceback (most recent call last):\n  File \"/Users/ohoriryosuke/20250417_synthepseai/SynthepseAI/workspace/project_429014e3-f05f-48f2-adf4-81de7dd29ac3/task_7f011f25-060f-47ae-a519-d602ad7c105e.py\", line 885, in main\n    task_start_time = prepare_task()\n                      ^^^^^^^^^^^^^^\n  File \"/Users/ohoriryosuke/20250417_synthepseai/SynthepseAI/workspace/project_429014e3-f05f-48f2-adf4-81de7dd29ac3/task_7f011f25-060f-47ae-a519-d602ad7c105e.py\", line 385, in prepare_task\n    return time.time()\n           ^^^^\nUnboundLocalError: cannot access local variable 'time' where it is not associated with a value\n"}}\n{"timestamp": 1747194716.650058, "type": "knowledge_update", "content": {"subject": "エラーパターン: UnboundLocalError", "original_fact": "タスク実行中に発生: {str(e)}", "new_fact": "タスク実行中に発生: {str(e)}", "confidence": 0.7, "source": null, "success": true}}\n{"timestamp": 1747194759.649738, "type": "task_execution_error", "content": {"task": "Unknown task", "error_type": "UnboundLocalError", "error_message": "cannot access local variable 'time' where it is not associated with a value", "traceback": "Traceback (most recent call last):\n  File \"/Users/ohoriryosuke/20250417_synthepseai/SynthepseAI/workspace/project_429014e3-f05f-48f2-adf4-81de7dd29ac3/task_3512d154-1317-4581-88dc-435273644ca2.py\", line 325, in prepare_task\n    task_start_time = time.time()\n                      ^^^^\nUnboundLocalError: cannot access local variable 'time' where it is not associated with a value\n\nDuring handling of the above exception, another exception occurred:\n\nTraceback (most recent call last):\n  File \"/Users/ohoriryosuke/20250417_synthepseai/SynthepseAI/workspace/project_429014e3-f05f-48f2-adf4-81de7dd29ac3/task_3512d154-1317-4581-88dc-435273644ca2.py\", line 885, in main\n    task_start_time = prepare_task()\n                      ^^^^^^^^^^^^^^\n  File \"/Users/ohoriryosuke/20250417_synthepseai/SynthepseAI/workspace/project_429014e3-f05f-48f2-adf4-81de7dd29ac3/task_3512d154-1317-4581-88dc-435273644ca2.py\", line 385, in prepare_task\n    return time.time()\n           ^^^^\nUnboundLocalError: cannot access local variable 'time' where it is not associated with a value\n"}}\n{"timestamp": 1747194759.6504571, "type": "knowledge_update", "content": {"subject": "エラーパターン: UnboundLocalError", "original_fact": "タスク実行中に発生: {str(e)}", "new_fact": "タスク実行中に発生: {str(e)}", "confidence": 0.7, "source": null, "success": true}}\n{"timestamp": 1747194809.042559, "type": "task_execution_error", "content": {"task": "Unknown task", "error_type": "UnboundLocalError", "error_message": "cannot access local variable 'time' where it is not associated with a value", "traceback": "Traceback (most recent call last):\n  File \"/Users/ohoriryosuke/20250417_synthepseai/SynthepseAI/workspace/project_429014e3-f05f-48f2-adf4-81de7dd29ac3/task_50a0aff0-9166-4b27-8523-3262b19f5cdc.py\", line 325, in prepare_task\n    task_start_time = time.time()\n                      ^^^^\nUnboundLocalError: cannot access local variable 'time' where it is not associated with a value\n\nDuring handling of the above exception, another exception occurred:\n\nTraceback (most recent call last):\n  File \"/Users/ohoriryosuke/20250417_synthepseai/SynthepseAI/workspace/project_429014e3-f05f-48f2-adf4-81de7dd29ac3/task_50a0aff0-9166-4b27-8523-3262b19f5cdc.py\", line 885, in main\n    task_start_time = prepare_task()\n                      ^^^^^^^^^^^^^^\n  File \"/Users/ohoriryosuke/20250417_synthepseai/SynthepseAI/workspace/project_429014e3-f05f-48f2-adf4-81de7dd29ac3/task_50a0aff0-9166-4b27-8523-3262b19f5cdc.py\", line 385, in prepare_task\n    return time.time()\n           ^^^^\nUnboundLocalError: cannot access local variable 'time' where it is not associated with a value\n"}}\n{"timestamp": 1747194809.0433102, "type": "knowledge_update", "content": {"subject": "エラーパターン: UnboundLocalError", "original_fact": "タスク実行中に発生: {str(e)}", "new_fact": "タスク実行中に発生: {str(e)}", "confidence": 0.7, "source": null, "success": true}}\n{"timestamp": 1747194857.351341, "type": "task_execution_error", "content": {"task": "Unknown task", "error_type": "UnboundLocalError", "error_message": "cannot access local variable 'time' where it is not associated with a value", "traceback": "Traceback (most recent call last):\n  File \"/Users/ohoriryosuke/20250417_synthepseai/SynthepseAI/workspace/project_429014e3-f05f-48f2-adf4-81de7dd29ac3/task_1482d33f-459c-4093-b655-b3f6ba9ea84b.py\", line 325, in prepare_task\n    task_start_time = time.time()\n                      ^^^^\nUnboundLocalError: cannot access local variable 'time' where it is not associated with a value\n\nDuring handling of the above exception, another exception occurred:\n\nTraceback (most recent call last):\n  File \"/Users/ohoriryosuke/20250417_synthepseai/SynthepseAI/workspace/project_429014e3-f05f-48f2-adf4-81de7dd29ac3/task_1482d33f-459c-4093-b655-b3f6ba9ea84b.py\", line 885, in main\n    task_start_time = prepare_task()\n                      ^^^^^^^^^^^^^^\n  File \"/Users/ohoriryosuke/20250417_synthepseai/SynthepseAI/workspace/project_429014e3-f05f-48f2-adf4-81de7dd29ac3/task_1482d33f-459c-4093-b655-b3f6ba9ea84b.py\", line 385, in prepare_task\n    return time.time()\n           ^^^^\nUnboundLocalError: cannot access local variable 'time' where it is not associated with a value\n"}}\n{"timestamp": 1747194857.352198, "type": "knowledge_update", "content": {"subject": "エラーパターン: UnboundLocalError", "original_fact": "タスク実行中に発生: {str(e)}", "new_fact": "タスク実行中に発生: {str(e)}", "confidence": 0.7, "source": null, "success": true}}\n{"timestamp": 1747194908.625303, "type": "task_execution_error", "content": {"task": "Unknown task", "error_type": "UnboundLocalError", "error_message": "cannot access local variable 'time' where it is not associated with a value", "traceback": "Traceback (most recent call last):\n  File \"/Users/ohoriryosuke/20250417_synthepseai/SynthepseAI/workspace/project_429014e3-f05f-48f2-adf4-81de7dd29ac3/task_7c7e94a6-2486-4808-8a2b-64c3696e966e.py\", line 325, in prepare_task\n    task_start_time = time.time()\n                      ^^^^\nUnboundLocalError: cannot access local variable 'time' where it is not associated with a value\n\nDuring handling of the above exception, another exception occurred:\n\nTraceback (most recent call last):\n  File \"/Users/ohoriryosuke/20250417_synthepseai/SynthepseAI/workspace/project_429014e3-f05f-48f2-adf4-81de7dd29ac3/task_7c7e94a6-2486-4808-8a2b-64c3696e966e.py\", line 885, in main\n    task_start_time = prepare_task()\n                      ^^^^^^^^^^^^^^\n  File \"/Users/ohoriryosuke/20250417_synthepseai/SynthepseAI/workspace/project_429014e3-f05f-48f2-adf4-81de7dd29ac3/task_7c7e94a6-2486-4808-8a2b-64c3696e966e.py\", line 385, in prepare_task\n    return time.time()\n           ^^^^\nUnboundLocalError: cannot access local variable 'time' where it is not associated with a value\n"}}\n{"timestamp": 1747194908.625976, "type": "knowledge_update", "content": {"subject": "エラーパターン: UnboundLocalError", "original_fact": "タスク実行中に発生: {str(e)}", "new_fact": "タスク実行中に発生: {str(e)}", "confidence": 0.7, "source": null, "success": true}}\n