{"timestamp": 1746799963.906254, "type": "task_execution_error", "content": {"task": "Unknown task", "error_type": "UnboundLocalError", "error_message": "cannot access local variable 'time' where it is not associated with a value", "traceback": "Traceback (most recent call last):\n  File \"/Users/ohoriryosuke/20250417_synthepseai/SynthepseAI/workspace/project_d2771c21-643d-4913-8d97-5a17508ad159/task_68fdae27-d2e6-4372-8467-f1852444ccfd.py\", line 325, in prepare_task\n    task_start_time = time.time()\n                      ^^^^\nUnboundLocalError: cannot access local variable 'time' where it is not associated with a value\n\nDuring handling of the above exception, another exception occurred:\n\nTraceback (most recent call last):\n  File \"/Users/ohoriryosuke/20250417_synthepseai/SynthepseAI/workspace/project_d2771c21-643d-4913-8d97-5a17508ad159/task_68fdae27-d2e6-4372-8467-f1852444ccfd.py\", line 931, in main\n    task_start_time = prepare_task()\n                      ^^^^^^^^^^^^^^\n  File \"/Users/ohoriryosuke/20250417_synthepseai/SynthepseAI/workspace/project_d2771c21-643d-4913-8d97-5a17508ad159/task_68fdae27-d2e6-4372-8467-f1852444ccfd.py\", line 385, in prepare_task\n    return time.time()\n           ^^^^\nUnboundLocalError: cannot access local variable 'time' where it is not associated with a value\n"}}\n{"timestamp": 1746799963.906487, "type": "knowledge_update", "content": {"subject": "エラーパターン: UnboundLocalError", "original_fact": null, "new_fact": "タスク実行中に発生: cannot access local variable 'time' where it is not associated with a value", "confidence": 0.7, "source": null, "success": true}}\n{"timestamp": 1746800019.1670551, "type": "task_execution_error", "content": {"task": "Unknown task", "error_type": "UnboundLocalError", "error_message": "cannot access local variable 'time' where it is not associated with a value", "traceback": "Traceback (most recent call last):\n  File \"/Users/ohoriryosuke/20250417_synthepseai/SynthepseAI/workspace/project_d2771c21-643d-4913-8d97-5a17508ad159/task_1d9b1ba0-bcfc-4ef6-8473-4bc94b8aaa8a.py\", line 325, in prepare_task\n    task_start_time = time.time()\n                      ^^^^\nUnboundLocalError: cannot access local variable 'time' where it is not associated with a value\n\nDuring handling of the above exception, another exception occurred:\n\nTraceback (most recent call last):\n  File \"/Users/ohoriryosuke/20250417_synthepseai/SynthepseAI/workspace/project_d2771c21-643d-4913-8d97-5a17508ad159/task_1d9b1ba0-bcfc-4ef6-8473-4bc94b8aaa8a.py\", line 931, in main\n    task_start_time = prepare_task()\n                      ^^^^^^^^^^^^^^\n  File \"/Users/ohoriryosuke/20250417_synthepseai/SynthepseAI/workspace/project_d2771c21-643d-4913-8d97-5a17508ad159/task_1d9b1ba0-bcfc-4ef6-8473-4bc94b8aaa8a.py\", line 385, in prepare_task\n    return time.time()\n           ^^^^\nUnboundLocalError: cannot access local variable 'time' where it is not associated with a value\n"}}\n{"timestamp": 1746800019.1673222, "type": "knowledge_update", "content": {"subject": "エラーパターン: UnboundLocalError", "original_fact": "タスク実行中に発生: cannot access local variable 'time' where it is not associated with a value", "new_fact": "タスク実行中に発生: cannot access local variable 'time' where it is not associated with a value", "confidence": 0.7, "source": null, "success": true}}\n{"timestamp": 1746800072.200366, "type": "task_execution_error", "content": {"task": "Unknown task", "error_type": "UnboundLocalError", "error_message": "cannot access local variable 'time' where it is not associated with a value", "traceback": "Traceback (most recent call last):\n  File \"/Users/ohoriryosuke/20250417_synthepseai/SynthepseAI/workspace/project_d2771c21-643d-4913-8d97-5a17508ad159/task_7f9b5525-de13-49d8-8798-6681a04170ce.py\", line 325, in prepare_task\n    task_start_time = time.time()\n                      ^^^^\nUnboundLocalError: cannot access local variable 'time' where it is not associated with a value\n\nDuring handling of the above exception, another exception occurred:\n\nTraceback (most recent call last):\n  File \"/Users/ohoriryosuke/20250417_synthepseai/SynthepseAI/workspace/project_d2771c21-643d-4913-8d97-5a17508ad159/task_7f9b5525-de13-49d8-8798-6681a04170ce.py\", line 931, in main\n    task_start_time = prepare_task()\n                      ^^^^^^^^^^^^^^\n  File \"/Users/ohoriryosuke/20250417_synthepseai/SynthepseAI/workspace/project_d2771c21-643d-4913-8d97-5a17508ad159/task_7f9b5525-de13-49d8-8798-6681a04170ce.py\", line 385, in prepare_task\n    return time.time()\n           ^^^^\nUnboundLocalError: cannot access local variable 'time' where it is not associated with a value\n"}}\n{"timestamp": 1746800072.200672, "type": "knowledge_update", "content": {"subject": "エラーパターン: UnboundLocalError", "original_fact": "タスク実行中に発生: cannot access local variable 'time' where it is not associated with a value", "new_fact": "タスク実行中に発生: cannot access local variable 'time' where it is not associated with a value", "confidence": 0.7, "source": null, "success": true}}\n{"timestamp": 1746800129.197071, "type": "task_execution_error", "content": {"task": "Unknown task", "error_type": "UnboundLocalError", "error_message": "cannot access local variable 'time' where it is not associated with a value", "traceback": "Traceback (most recent call last):\n  File \"/Users/ohoriryosuke/20250417_synthepseai/SynthepseAI/workspace/project_d2771c21-643d-4913-8d97-5a17508ad159/task_9ac63a43-0979-4060-83eb-195e5bfed148.py\", line 325, in prepare_task\n    task_start_time = time.time()\n                      ^^^^\nUnboundLocalError: cannot access local variable 'time' where it is not associated with a value\n\nDuring handling of the above exception, another exception occurred:\n\nTraceback (most recent call last):\n  File \"/Users/ohoriryosuke/20250417_synthepseai/SynthepseAI/workspace/project_d2771c21-643d-4913-8d97-5a17508ad159/task_9ac63a43-0979-4060-83eb-195e5bfed148.py\", line 931, in main\n    task_start_time = prepare_task()\n                      ^^^^^^^^^^^^^^\n  File \"/Users/ohoriryosuke/20250417_synthepseai/SynthepseAI/workspace/project_d2771c21-643d-4913-8d97-5a17508ad159/task_9ac63a43-0979-4060-83eb-195e5bfed148.py\", line 385, in prepare_task\n    return time.time()\n           ^^^^\nUnboundLocalError: cannot access local variable 'time' where it is not associated with a value\n"}}\n{"timestamp": 1746800129.1973162, "type": "knowledge_update", "content": {"subject": "エラーパターン: UnboundLocalError", "original_fact": "タスク実行中に発生: cannot access local variable 'time' where it is not associated with a value", "new_fact": "タスク実行中に発生: cannot access local variable 'time' where it is not associated with a value", "confidence": 0.7, "source": null, "success": true}}\n{"timestamp": 1746800174.909306, "type": "task_execution_error", "content": {"task": "Unknown task", "error_type": "UnboundLocalError", "error_message": "cannot access local variable 'time' where it is not associated with a value", "traceback": "Traceback (most recent call last):\n  File \"/Users/ohoriryosuke/20250417_synthepseai/SynthepseAI/workspace/project_d2771c21-643d-4913-8d97-5a17508ad159/task_a9d695d3-4db3-4bf1-82a8-9d8e8482a661.py\", line 325, in prepare_task\n    task_start_time = time.time()\n                      ^^^^\nUnboundLocalError: cannot access local variable 'time' where it is not associated with a value\n\nDuring handling of the above exception, another exception occurred:\n\nTraceback (most recent call last):\n  File \"/Users/ohoriryosuke/20250417_synthepseai/SynthepseAI/workspace/project_d2771c21-643d-4913-8d97-5a17508ad159/task_a9d695d3-4db3-4bf1-82a8-9d8e8482a661.py\", line 931, in main\n    task_start_time = prepare_task()\n                      ^^^^^^^^^^^^^^\n  File \"/Users/ohoriryosuke/20250417_synthepseai/SynthepseAI/workspace/project_d2771c21-643d-4913-8d97-5a17508ad159/task_a9d695d3-4db3-4bf1-82a8-9d8e8482a661.py\", line 385, in prepare_task\n    return time.time()\n           ^^^^\nUnboundLocalError: cannot access local variable 'time' where it is not associated with a value\n"}}\n{"timestamp": 1746800174.909569, "type": "knowledge_update", "content": {"subject": "エラーパターン: UnboundLocalError", "original_fact": "タスク実行中に発生: cannot access local variable 'time' where it is not associated with a value", "new_fact": "タスク実行中に発生: cannot access local variable 'time' where it is not associated with a value", "confidence": 0.7, "source": null, "success": true}}\n{"timestamp": 1746800223.936637, "type": "task_execution_error", "content": {"task": "Unknown task", "error_type": "UnboundLocalError", "error_message": "cannot access local variable 'time' where it is not associated with a value", "traceback": "Traceback (most recent call last):\n  File \"/Users/ohoriryosuke/20250417_synthepseai/SynthepseAI/workspace/project_d2771c21-643d-4913-8d97-5a17508ad159/task_d73da5ec-4f28-4d83-abcd-1627a06bf84a.py\", line 325, in prepare_task\n    task_start_time = time.time()\n                      ^^^^\nUnboundLocalError: cannot access local variable 'time' where it is not associated with a value\n\nDuring handling of the above exception, another exception occurred:\n\nTraceback (most recent call last):\n  File \"/Users/ohoriryosuke/20250417_synthepseai/SynthepseAI/workspace/project_d2771c21-643d-4913-8d97-5a17508ad159/task_d73da5ec-4f28-4d83-abcd-1627a06bf84a.py\", line 931, in main\n    task_start_time = prepare_task()\n                      ^^^^^^^^^^^^^^\n  File \"/Users/ohoriryosuke/20250417_synthepseai/SynthepseAI/workspace/project_d2771c21-643d-4913-8d97-5a17508ad159/task_d73da5ec-4f28-4d83-abcd-1627a06bf84a.py\", line 385, in prepare_task\n    return time.time()\n           ^^^^\nUnboundLocalError: cannot access local variable 'time' where it is not associated with a value\n"}}\n{"timestamp": 1746800223.936964, "type": "knowledge_update", "content": {"subject": "エラーパターン: UnboundLocalError", "original_fact": "タスク実行中に発生: cannot access local variable 'time' where it is not associated with a value", "new_fact": "タスク実行中に発生: cannot access local variable 'time' where it is not associated with a value", "confidence": 0.7, "source": null, "success": true}}\n{"timestamp": 1746800277.476872, "type": "task_execution_error", "content": {"task": "Unknown task", "error_type": "UnboundLocalError", "error_message": "cannot access local variable 'time' where it is not associated with a value", "traceback": "Traceback (most recent call last):\n  File \"/Users/ohoriryosuke/20250417_synthepseai/SynthepseAI/workspace/project_d2771c21-643d-4913-8d97-5a17508ad159/task_8cec8c68-ef41-495d-86c7-d54dd9f1825d.py\", line 325, in prepare_task\n    task_start_time = time.time()\n                      ^^^^\nUnboundLocalError: cannot access local variable 'time' where it is not associated with a value\n\nDuring handling of the above exception, another exception occurred:\n\nTraceback (most recent call last):\n  File \"/Users/ohoriryosuke/20250417_synthepseai/SynthepseAI/workspace/project_d2771c21-643d-4913-8d97-5a17508ad159/task_8cec8c68-ef41-495d-86c7-d54dd9f1825d.py\", line 931, in main\n    task_start_time = prepare_task()\n                      ^^^^^^^^^^^^^^\n  File \"/Users/ohoriryosuke/20250417_synthepseai/SynthepseAI/workspace/project_d2771c21-643d-4913-8d97-5a17508ad159/task_8cec8c68-ef41-495d-86c7-d54dd9f1825d.py\", line 385, in prepare_task\n    return time.time()\n           ^^^^\nUnboundLocalError: cannot access local variable 'time' where it is not associated with a value\n"}}\n{"timestamp": 1746800277.4771242, "type": "knowledge_update", "content": {"subject": "エラーパターン: UnboundLocalError", "original_fact": "タスク実行中に発生: cannot access local variable 'time' where it is not associated with a value", "new_fact": "タスク実行中に発生: cannot access local variable 'time' where it is not associated with a value", "confidence": 0.7, "source": null, "success": true}}\n{"timestamp": 1746800318.988961, "type": "task_execution_error", "content": {"task": "Unknown task", "error_type": "UnboundLocalError", "error_message": "cannot access local variable 'time' where it is not associated with a value", "traceback": "Traceback (most recent call last):\n  File \"/Users/ohoriryosuke/20250417_synthepseai/SynthepseAI/workspace/project_d2771c21-643d-4913-8d97-5a17508ad159/task_dca0c7d5-648d-4c5a-84b7-082fc130b268.py\", line 325, in prepare_task\n    task_start_time = time.time()\n                      ^^^^\nUnboundLocalError: cannot access local variable 'time' where it is not associated with a value\n\nDuring handling of the above exception, another exception occurred:\n\nTraceback (most recent call last):\n  File \"/Users/ohoriryosuke/20250417_synthepseai/SynthepseAI/workspace/project_d2771c21-643d-4913-8d97-5a17508ad159/task_dca0c7d5-648d-4c5a-84b7-082fc130b268.py\", line 931, in main\n    task_start_time = prepare_task()\n                      ^^^^^^^^^^^^^^\n  File \"/Users/ohoriryosuke/20250417_synthepseai/SynthepseAI/workspace/project_d2771c21-643d-4913-8d97-5a17508ad159/task_dca0c7d5-648d-4c5a-84b7-082fc130b268.py\", line 385, in prepare_task\n    return time.time()\n           ^^^^\nUnboundLocalError: cannot access local variable 'time' where it is not associated with a value\n"}}\n{"timestamp": 1746800318.989373, "type": "knowledge_update", "content": {"subject": "エラーパターン: UnboundLocalError", "original_fact": "タスク実行中に発生: cannot access local variable 'time' where it is not associated with a value", "new_fact": "タスク実行中に発生: cannot access local variable 'time' where it is not associated with a value", "confidence": 0.7, "source": null, "success": true}}\n{"timestamp": 1746800374.5661, "type": "task_execution_error", "content": {"task": "Unknown task", "error_type": "UnboundLocalError", "error_message": "cannot access local variable 'time' where it is not associated with a value", "traceback": "Traceback (most recent call last):\n  File \"/Users/ohoriryosuke/20250417_synthepseai/SynthepseAI/workspace/project_d2771c21-643d-4913-8d97-5a17508ad159/task_b398bb2e-e40c-4bc1-9d6b-7eb7f8f6a321.py\", line 325, in prepare_task\n    task_start_time = time.time()\n                      ^^^^\nUnboundLocalError: cannot access local variable 'time' where it is not associated with a value\n\nDuring handling of the above exception, another exception occurred:\n\nTraceback (most recent call last):\n  File \"/Users/ohoriryosuke/20250417_synthepseai/SynthepseAI/workspace/project_d2771c21-643d-4913-8d97-5a17508ad159/task_b398bb2e-e40c-4bc1-9d6b-7eb7f8f6a321.py\", line 931, in main\n    task_start_time = prepare_task()\n                      ^^^^^^^^^^^^^^\n  File \"/Users/ohoriryosuke/20250417_synthepseai/SynthepseAI/workspace/project_d2771c21-643d-4913-8d97-5a17508ad159/task_b398bb2e-e40c-4bc1-9d6b-7eb7f8f6a321.py\", line 385, in prepare_task\n    return time.time()\n           ^^^^\nUnboundLocalError: cannot access local variable 'time' where it is not associated with a value\n"}}\n{"timestamp": 1746800374.566454, "type": "knowledge_update", "content": {"subject": "エラーパターン: UnboundLocalError", "original_fact": "タスク実行中に発生: cannot access local variable 'time' where it is not associated with a value", "new_fact": "タスク実行中に発生: cannot access local variable 'time' where it is not associated with a value", "confidence": 0.7, "source": null, "success": true}}\n{"timestamp": 1746800429.131595, "type": "task_execution_error", "content": {"task": "Unknown task", "error_type": "UnboundLocalError", "error_message": "cannot access local variable 'time' where it is not associated with a value", "traceback": "Traceback (most recent call last):\n  File \"/Users/ohoriryosuke/20250417_synthepseai/SynthepseAI/workspace/project_d2771c21-643d-4913-8d97-5a17508ad159/task_fdafc3d2-0914-43de-9948-ef9a74b062cb.py\", line 326, in prepare_task\n    task_start_time = time.time()\n                      ^^^^\nUnboundLocalError: cannot access local variable 'time' where it is not associated with a value\n\nDuring handling of the above exception, another exception occurred:\n\nTraceback (most recent call last):\n  File \"/Users/ohoriryosuke/20250417_synthepseai/SynthepseAI/workspace/project_d2771c21-643d-4913-8d97-5a17508ad159/task_fdafc3d2-0914-43de-9948-ef9a74b062cb.py\", line 932, in main\n    task_start_time = prepare_task()\n                      ^^^^^^^^^^^^^^\n  File \"/Users/ohoriryosuke/20250417_synthepseai/SynthepseAI/workspace/project_d2771c21-643d-4913-8d97-5a17508ad159/task_fdafc3d2-0914-43de-9948-ef9a74b062cb.py\", line 386, in prepare_task\n    return time.time()\n           ^^^^\nUnboundLocalError: cannot access local variable 'time' where it is not associated with a value\n"}}\n{"timestamp": 1746800429.1318998, "type": "knowledge_update", "content": {"subject": "エラーパターン: UnboundLocalError", "original_fact": "タスク実行中に発生: cannot access local variable 'time' where it is not associated with a value", "new_fact": "タスク実行中に発生: cannot access local variable 'time' where it is not associated with a value", "confidence": 0.7, "source": null, "success": true}}\n